RuntimeError: module compiled against API version 0x10 but this version of numpy is 0xe
RuntimeError: module compiled against API version 0x10 but this version of numpy is 0xe
ImportError: numpy.core.multiarray failed to import

The above exception was the direct cause of the following exception:

SystemError: <built-in method __contains__ of dict object at 0x7f36b1a14f80> returned a result with an error set

The above exception was the direct cause of the following exception:

Traceback (most recent call last):
  File "/lus/theta-fs0/software/thetagpu/conda/2022-07-01/mconda3/lib/python3.8/site-packages/transformers/utils/import_utils.py", line 905, in _get_module
    return importlib.import_module("." + module_name, self.__name__)
  File "/lus/theta-fs0/software/thetagpu/conda/2022-07-01/mconda3/lib/python3.8/importlib/__init__.py", line 127, in import_module
    return _bootstrap._gcd_import(name[level:], package, level)
  File "<frozen importlib._bootstrap>", line 1014, in _gcd_import
  File "<frozen importlib._bootstrap>", line 991, in _find_and_load
  File "<frozen importlib._bootstrap>", line 975, in _find_and_load_unlocked
  File "<frozen importlib._bootstrap>", line 671, in _load_unlocked
  File "<frozen importlib._bootstrap_external>", line 843, in exec_module
  File "<frozen importlib._bootstrap>", line 219, in _call_with_frames_removed
  File "/lus/theta-fs0/software/thetagpu/conda/2022-07-01/mconda3/lib/python3.8/site-packages/transformers/pipelines/__init__.py", line 34, in <module>
    from .audio_classification import AudioClassificationPipeline
  File "/lus/theta-fs0/software/thetagpu/conda/2022-07-01/mconda3/lib/python3.8/site-packages/transformers/pipelines/audio_classification.py", line 20, in <module>
    from .base import PIPELINE_INIT_ARGS, Pipeline
  File "/lus/theta-fs0/software/thetagpu/conda/2022-07-01/mconda3/lib/python3.8/site-packages/transformers/pipelines/base.py", line 33, in <module>
    from ..modelcard import ModelCard
  File "/lus/theta-fs0/software/thetagpu/conda/2022-07-01/mconda3/lib/python3.8/site-packages/transformers/modelcard.py", line 44, in <module>
    from .training_args import ParallelMode
  File "/lus/theta-fs0/software/thetagpu/conda/2022-07-01/mconda3/lib/python3.8/site-packages/transformers/training_args.py", line 26, in <module>
    from .trainer_utils import (
  File "/lus/theta-fs0/software/thetagpu/conda/2022-07-01/mconda3/lib/python3.8/site-packages/transformers/trainer_utils.py", line 47, in <module>
    import tensorflow as tf
  File "/lus/theta-fs0/software/thetagpu/conda/2022-07-01/mconda3/lib/python3.8/site-packages/tensorflow/__init__.py", line 37, in <module>
    from tensorflow.python.tools import module_util as _module_util
  File "/lus/theta-fs0/software/thetagpu/conda/2022-07-01/mconda3/lib/python3.8/site-packages/tensorflow/python/__init__.py", line 37, in <module>
    from tensorflow.python.eager import context
  File "/lus/theta-fs0/software/thetagpu/conda/2022-07-01/mconda3/lib/python3.8/site-packages/tensorflow/python/eager/context.py", line 35, in <module>
    from tensorflow.python.client import pywrap_tf_session
  File "/lus/theta-fs0/software/thetagpu/conda/2022-07-01/mconda3/lib/python3.8/site-packages/tensorflow/python/client/pywrap_tf_session.py", line 19, in <module>
    from tensorflow.python.client._pywrap_tf_session import *
ImportError: initialization failed

The above exception was the direct cause of the following exception:

Traceback (most recent call last):
  File "import_evaluate.py", line 1, in <module>
    import evaluate
  File "/lus/theta-fs0/software/thetagpu/conda/2022-07-01/mconda3/lib/python3.8/site-packages/evaluate/__init__.py", line 29, in <module>
    from .evaluation_suite import EvaluationSuite
  File "/lus/theta-fs0/software/thetagpu/conda/2022-07-01/mconda3/lib/python3.8/site-packages/evaluate/evaluation_suite/__init__.py", line 10, in <module>
    from ..evaluator import evaluator
  File "/lus/theta-fs0/software/thetagpu/conda/2022-07-01/mconda3/lib/python3.8/site-packages/evaluate/evaluator/__init__.py", line 27, in <module>
    from .automatic_speech_recognition import AutomaticSpeechRecognitionEvaluator
  File "/lus/theta-fs0/software/thetagpu/conda/2022-07-01/mconda3/lib/python3.8/site-packages/evaluate/evaluator/automatic_speech_recognition.py", line 22, in <module>
    from .base import EVALUATOR_COMPUTE_RETURN_DOCSTRING, EVALUTOR_COMPUTE_START_DOCSTRING, Evaluator
  File "/lus/theta-fs0/software/thetagpu/conda/2022-07-01/mconda3/lib/python3.8/site-packages/evaluate/evaluator/base.py", line 34, in <module>
    from transformers import Pipeline, pipeline
  File "<frozen importlib._bootstrap>", line 1039, in _handle_fromlist
  File "/lus/theta-fs0/software/thetagpu/conda/2022-07-01/mconda3/lib/python3.8/site-packages/transformers/utils/import_utils.py", line 895, in __getattr__
    module = self._get_module(self._class_to_module[name])
  File "/lus/theta-fs0/software/thetagpu/conda/2022-07-01/mconda3/lib/python3.8/site-packages/transformers/utils/import_utils.py", line 907, in _get_module
    raise RuntimeError(
RuntimeError: Failed to import transformers.pipelines because of the following error (look up to see its traceback):
initialization failed
